<mujoco model="cheetah">
  <compiler angle="radian" coordinate="local" inertiafromgeom="true" settotalmass="14"/>
  <default>
    <joint armature=".1" damping=".01" limited="true" solimplimit="0 .8 .03" solreflimit=".02 1" stiffness="0"/>
    <geom conaffinity="0" condim="3" contype="1" friction=".4 .1 .1" rgba="0.8 0.6 .4 1" solimp="0.0 0.8 0.01" solref="0.02 1"/>
    <motor ctrllimited="true" ctrlrange="-1 1"/>
  </default>
  <size nstack="300000" nuser_geom="1"/>
  <option gravity="0 0 -9.81" timestep="0.01"/>
  <asset>
    <texture builtin="gradient" height="100" rgb1="1 1 1" rgb2="0 0 0" type="skybox" width="100"/>
    <texture builtin="flat" height="1278" mark="cross" markrgb="1 1 1" name="texgeom" random="0.01" rgb1="0.8 0.6 0.4" rgb2="0.8 0.6 0.4" type="cube" width="127"/>
    <texture builtin="checker" height="100" name="texplane" rgb1="0 0 0" rgb2="0.8 0.8 0.8" type="2d" width="100"/>
    <material name="MatPlane" reflectance="0.5" shininess="1" specular="1" texrepeat="60 60" texture="texplane"/>
    <material name="geom" texture="texgeom" texuniform="true"/>
  </asset>
  <worldbody>
    <light cutoff="100" diffuse="1 1 1" dir="-0 0 -1.3" directional="true" exponent="1" pos="0 0 1.3" specular=".1 .1 .1"/>
    <geom conaffinity="1" condim="3" material="MatPlane" name="floor" pos="0 0 0" rgba="0.8 0.9 0.8 1" size="40 40 40" type="plane"/>

    <body name="current_vel_lin" pos="0 0 0">
      <geom conaffinity="8" contype="4" axisangle="1 0 0 0" name="current_vel_lin" pos="0 0 0" size="0.05 .15" type="capsule" rgba="0 0.8 0 1"/>
    </body>

    <body name="current_vel_rot" pos="0 0 0">
      <geom conaffinity="8" contype="4" axisangle="1 0 0 0" name="current_vel_rot" pos="0 0 0" size="0.05 .15" type="capsule" rgba="0.8 0.8 0 1"/>
    </body>

    <body name="target_vel_lin" pos="0 0 0">
      <geom conaffinity="8" contype="4" axisangle="1 0 0 0" name="target_vel_lin" pos="0 0 0" size="0.05 .15" type="capsule" rgba="0 0 0.8 1"/>
    </body>

    <body name="target_vel_rot" pos="0 0 0">
      <geom conaffinity="8" contype="4" axisangle="1 0 0 0" name="target_vel_rot" pos="0 0 0" size="0.05 .15" type="capsule" rgba="0.8 0 0.8 1"/>
    </body>

    <body name="torso" pos="0 0 1.7">
      <camera name="track" mode="trackcom" pos="0 -3 0.3" xyaxes="1 0 0 0 0 1"/>
      <joint armature="0" axis="1 0 0" damping="0" limited="false" name="root" pos="0 0 0" type="free"/>
      <geom name="torso" size=".4 .3 .05" type="box"/>
      <geom axisangle="0 1 0 .87" name="head" pos=".6 0 .1" size="0.046 .15" type="capsule"/>

      <body name="leg1_top" pos="-.5 .3 0">
        <joint axis="1 0 0" damping="6" name="leg1_top_side" pos="0 0 0" range="-1 1" type="hinge"/>
        <joint axis="0 1 0" damping="6" name="leg1_top_fwd" pos="0 0 0" range="-1 1" type="hinge"/>
        <geom axisangle="0 1 0 0" name="leg1_top" pos="0 0 -0.3" size="0.05 .24" type="capsule"/>
        <body name="leg1_mid" pos="0 0 -0.6">
          <joint axis="0 1 0" damping="6" name="leg1_mid" pos="0 0 0" range="-1 1" type="hinge"/>
          <geom axisangle="0 1 0 0" name="leg1_mid" pos="0 0 -0.3" rgba="0.9 0.5 0.5 1" size="0.05 .24" type="capsule"/>
        </body>
      </body>

      <body name="leg2_top" pos="-.5 -.3 0">
        <joint axis="1 0 0" damping="6" name="leg2_top_side" pos="0 0 0" range="-1 1" type="hinge"/>
        <joint axis="0 1 0" damping="6" name="leg2_top_fwd" pos="0 0 0" range="-1 1" type="hinge"/>
        <geom axisangle="0 1 0 0" name="leg2_top" pos="0 0 -0.3" size="0.05 .24" type="capsule"/>
        <body name="leg2_mid" pos="0 0 -0.6">
          <joint axis="0 1 0" damping="6" name="leg2_mid" pos="0 0 0" range="-1 1" type="hinge"/>
          <geom axisangle="0 1 0 0" name="leg2_mid" pos="0 0 -0.3" rgba="0.9 0.5 0.5 1" size="0.05 .24" type="capsule"/>
        </body>
      </body>

      <body name="leg3_top" pos=".5 .3 0">
        <joint axis="1 0 0" damping="6" name="leg3_top_side" pos="0 0 0" range="-1 1" type="hinge"/>
        <joint axis="0 1 0" damping="6" name="leg3_top_fwd" pos="0 0 0" range="-1 1" type="hinge"/>
        <geom axisangle="0 1 0 0" name="leg3_top" pos="0 0 -0.3" size="0.05 .24" type="capsule"/>
        <body name="leg3_mid" pos="0 0 -0.6">
          <joint axis="0 1 0" damping="6" name="leg3_mid" pos="0 0 0" range="-1 1" type="hinge"/>
          <geom axisangle="0 1 0 0" name="leg3_mid" pos="0 0 -0.3" rgba="0.9 0.5 0.5 1" size="0.05 .24" type="capsule"/>
        </body>
      </body>

      <body name="leg4_top" pos=".5 -.3 0">
        <joint axis="1 0 0" damping="6" name="leg4_top_side" pos="0 0 0" range="-1 1" type="hinge"/>
        <joint axis="0 1 0" damping="6" name="leg4_top_fwd" pos="0 0 0" range="-1 1" type="hinge"/>
        <geom axisangle="0 1 0 0" name="leg4_top" pos="0 0 -0.3" size="0.05 .24" type="capsule"/>
        <body name="leg4_mid" pos="0 0 -0.6">
          <joint axis="0 1 0" damping="6" name="leg4_mid" pos="0 0 0" range="-1 1" type="hinge"/>
          <geom axisangle="0 1 0 0" name="leg4_mid" pos="0 0 -0.3" rgba="0.9 0.5 0.5 1" size="0.05 .24" type="capsule"/>
        </body>
      </body>

    </body>
  </worldbody>
  <actuator>

    <motor gear="120" joint="leg1_top_side" name="leg1_top_side"/>
    <motor gear="120" joint="leg1_top_fwd" name="leg1_top_fwd"/>
    <motor gear="120" joint="leg1_mid" name="leg1_mid"/>

    <motor gear="120" joint="leg2_top_side" name="leg2_top_side"/>
    <motor gear="120" joint="leg2_top_fwd" name="leg2_top_fwd"/>
    <motor gear="120" joint="leg2_mid" name="leg2_mid"/>

    <motor gear="120" joint="leg3_top_side" name="leg3_top_side"/>
    <motor gear="120" joint="leg3_top_fwd" name="leg3_top_fwd"/>
    <motor gear="120" joint="leg3_mid" name="leg3_mid"/>

    <motor gear="120" joint="leg4_top_side" name="leg4_top_side"/>
    <motor gear="120" joint="leg4_top_fwd" name="leg4_top_fwd"/>
    <motor gear="120" joint="leg4_mid" name="leg4_mid"/>

  </actuator>
</mujoco>
